/usr/local/lib/python3.6/site-packages/requests/__init__.py:91: RequestsDependencyWarning: urllib3 (1.26.3) or chardet (3.0.4) doesn't match a supported version!
  RequestsDependencyWarning)
Traceback (most recent call last):
  File "/usr/local/lib/python3.6/site-packages/kfserving/api/kf_serving_client.py", line 107, in create
    inferenceservice)
  File "/usr/local/lib/python3.6/site-packages/kubernetes/client/apis/custom_objects_api.py", line 178, in create_namespaced_custom_object
    (data) = self.create_namespaced_custom_object_with_http_info(group, version, namespace, plural, body, **kwargs)
  File "/usr/local/lib/python3.6/site-packages/kubernetes/client/apis/custom_objects_api.py", line 277, in create_namespaced_custom_object_with_http_info
    collection_formats=collection_formats)
  File "/usr/local/lib/python3.6/site-packages/kubernetes/client/api_client.py", line 334, in call_api
    _return_http_data_only, collection_formats, _preload_content, _request_timeout)
  File "/usr/local/lib/python3.6/site-packages/kubernetes/client/api_client.py", line 168, in __call_api
    _request_timeout=_request_timeout)
  File "/usr/local/lib/python3.6/site-packages/kubernetes/client/api_client.py", line 377, in request
    body=body)
  File "/usr/local/lib/python3.6/site-packages/kubernetes/client/rest.py", line 266, in POST
    body=body)
  File "/usr/local/lib/python3.6/site-packages/kubernetes/client/rest.py", line 222, in request
    raise ApiException(http_resp=r)
kubernetes.client.rest.ApiException: (403)
Reason: Forbidden
HTTP response headers: HTTPHeaderDict({'Cache-Control': 'no-cache, private', 'Content-Type': 'application/json', 'X-Content-Type-Options': 'nosniff', 'X-Kubernetes-Pf-Flowschema-Uid': '300c9aac-34e8-4304-8740-b63006b8fc5a', 'X-Kubernetes-Pf-Prioritylevel-Uid': 'f1204eff-b1e2-4833-9e50-d5403dd8598b', 'Date': 'Fri, 03 Sep 2021 12:45:10 GMT', 'Content-Length': '404'})
HTTP response body: {"kind":"Status","apiVersion":"v1","metadata":{},"status":"Failure","message":"inferenceservices.serving.kubeflow.org is forbidden: User \"system:serviceaccount:kubeflow:pipeline-runner\" cannot create resource \"inferenceservices\" in API group \"serving.kubeflow.org\" in the namespace \"default\"","reason":"Forbidden","details":{"group":"serving.kubeflow.org","kind":"inferenceservices"},"code":403}
During handling of the above exception, another exception occurred:
Traceback (most recent call last):
  File "kfservingdeployer.py", line 245, in deploy_model
    create(kfsvc, model_name, namespace)
  File "kfservingdeployer.py", line 230, in create
    KFServing.create(kfsvc, namespace=namespace)
  File "/usr/local/lib/python3.6/site-packages/kfserving/api/kf_serving_client.py", line 111, in create
    %s\n" % e)
RuntimeError: Exception when calling CustomObjectsApi->create_namespaced_custom_object:                 (403)
Reason: Forbidden
HTTP response headers: HTTPHeaderDict({'Cache-Control': 'no-cache, private', 'Content-Type': 'application/json', 'X-Content-Type-Options': 'nosniff', 'X-Kubernetes-Pf-Flowschema-Uid': '300c9aac-34e8-4304-8740-b63006b8fc5a', 'X-Kubernetes-Pf-Prioritylevel-Uid': 'f1204eff-b1e2-4833-9e50-d5403dd8598b', 'Date': 'Fri, 03 Sep 2021 12:45:10 GMT', 'Content-Length': '404'})
HTTP response body: {"kind":"Status","apiVersion":"v1","metadata":{},"status":"Failure","message":"inferenceservices.serving.kubeflow.org is forbidden: User \"system:serviceaccount:kubeflow:pipeline-runner\" cannot create resource \"inferenceservices\" in API group \"serving.kubeflow.org\" in the namespace \"default\"","reason":"Forbidden","details":{"group":"serving.kubeflow.org","kind":"inferenceservices"},"code":403}
During handling of the above exception, another exception occurred:
Traceback (most recent call last):
  File "/usr/local/lib/python3.6/site-packages/kfserving/api/kf_serving_client.py", line 188, in patch
    inferenceservice)
  File "/usr/local/lib/python3.6/site-packages/kubernetes/client/apis/custom_objects_api.py", line 1951, in patch_namespaced_custom_object
    (data) = self.patch_namespaced_custom_object_with_http_info(group, version, namespace, plural, name, body, **kwargs)
  File "/usr/local/lib/python3.6/site-packages/kubernetes/client/apis/custom_objects_api.py", line 2057, in patch_namespaced_custom_object_with_http_info
    collection_formats=collection_formats)
  File "/usr/local/lib/python3.6/site-packages/kubernetes/client/api_client.py", line 334, in call_api
    _return_http_data_only, collection_formats, _preload_content, _request_timeout)
  File "/usr/local/lib/python3.6/site-packages/kubernetes/client/api_client.py", line 168, in __call_api
    _request_timeout=_request_timeout)
  File "/usr/local/lib/python3.6/site-packages/kubernetes/client/api_client.py", line 393, in request
    body=body)
  File "/usr/local/lib/python3.6/site-packages/kubernetes/client/rest.py", line 286, in PATCH
    body=body)
  File "/usr/local/lib/python3.6/site-packages/kubernetes/client/rest.py", line 222, in request
    raise ApiException(http_resp=r)
kubernetes.client.rest.ApiException: (403)
Reason: Forbidden
HTTP response headers: HTTPHeaderDict({'Cache-Control': 'no-cache, private', 'Content-Type': 'application/json', 'X-Content-Type-Options': 'nosniff', 'X-Kubernetes-Pf-Flowschema-Uid': '300c9aac-34e8-4304-8740-b63006b8fc5a', 'X-Kubernetes-Pf-Prioritylevel-Uid': 'f1204eff-b1e2-4833-9e50-d5403dd8598b', 'Date': 'Fri, 03 Sep 2021 12:45:10 GMT', 'Content-Length': '428'})
HTTP response body: {"kind":"Status","apiVersion":"v1","metadata":{},"status":"Failure","message":"inferenceservices.serving.kubeflow.org \"mnist\" is forbidden: User \"system:serviceaccount:kubeflow:pipeline-runner\" cannot patch resource \"inferenceservices\" in API group \"serving.kubeflow.org\" in the namespace \"default\"","reason":"Forbidden","details":{"name":"mnist","group":"serving.kubeflow.org","kind":"inferenceservices"},"code":403}
During handling of the above exception, another exception occurred:
Traceback (most recent call last):
  File "kfservingdeployer.py", line 417, in <module>
    max_replicas=max_replicas
  File "kfservingdeployer.py", line 247, in deploy_model
    update(kfsvc, model_name, namespace)
  File "kfservingdeployer.py", line 235, in update
    KFServing.patch(model_name, kfsvc, namespace=namespace)
  File "/usr/local/lib/python3.6/site-packages/kfserving/api/kf_serving_client.py", line 192, in patch
    %s\n" % e)
RuntimeError: Exception when calling CustomObjectsApi->patch_namespaced_custom_object:                 (403)
Reason: Forbidden
HTTP response headers: HTTPHeaderDict({'Cache-Control': 'no-cache, private', 'Content-Type': 'application/json', 'X-Content-Type-Options': 'nosniff', 'X-Kubernetes-Pf-Flowschema-Uid': '300c9aac-34e8-4304-8740-b63006b8fc5a', 'X-Kubernetes-Pf-Prioritylevel-Uid': 'f1204eff-b1e2-4833-9e50-d5403dd8598b', 'Date': 'Fri, 03 Sep 2021 12:45:10 GMT', 'Content-Length': '428'})
HTTP response body: {"kind":"Status","apiVersion":"v1","metadata":{},"status":"Failure","message":"inferenceservices.serving.kubeflow.org \"mnist\" is forbidden: User \"system:serviceaccount:kubeflow:pipeline-runner\" cannot patch resource \"inferenceservices\" in API group \"serving.kubeflow.org\" in the namespace \"default\"","reason":"Forbidden","details":{"name":"mnist","group":"serving.kubeflow.org","kind":"inferenceservices"},"code":403}
